16)What is the output of the following codes:

(i) def foo():
	try:
	   return 1
	finally:
	   return 2

	k = foo()
	print(k)

output: 2 as there is no exceptions


(ii) def a():
	try:
	  f(x, 4)
	finally:
	  print('after f')
	  print('after f?')
a()

output: there will be an error as f() is not defined